<?xml version="1.0"?>
<robot xmlns:xacro="http://wiki.ros.org/xacro">

  <xacro:macro name="hg_description" params="arm_id='hg' description_pkg:=''">
    <!-- LINKS -->
    <!-- base link -->
   <link
    name="${arm_id}_base_link">
    <inertial>
      <origin
        xyz="-0.0980500358272935 -0.00232771681565302 0.111852076506816"
        rpy="0 0 0" />
      <mass
        value="46.5873146529749" />
      <inertia
        ixx="0.661474745111325"
        ixy="0.0153527675183587"
        ixz="0.0896049534667292"
        iyy="1.33815915829418"
        iyz="0.000457536691791659"
        izz="1.80453325697265" />
    </inertial>
    <visual>
      <origin
        xyz="0 0 0"
        rpy="0 0 0" />
      <geometry>
        <mesh
          filename="package://${description_pkg}/meshes/base_link.STL" />
      </geometry>
      <material
        name="">
        <color
          rgba="0.792156862745098 0.819607843137255 0.933333333333333 1" />
      </material>
    </visual>
    <collision>
      <origin
        xyz="0 0 0"
        rpy="0 0 0" />
      <geometry>
        <mesh
          filename="package://${description_pkg}/meshes/base_link.STL" />
      </geometry>
    </collision>
  </link>
  <link
    name="${arm_id}_Link1">
    <inertial>
      <origin
        xyz="0.124489041842987 -0.0393581743565175 0.118219762696925"
        rpy="0 0 0" />
      <mass
        value="33.6330720996777" />
      <inertia
        ixx="0.468945917111701"
        ixy="-0.0589086006926277"
        ixz="-0.222059127197675"
        iyy="0.888555909330909"
        iyz="-0.0161423969436969"
        izz="0.843325415713474" />
    </inertial>
    <visual>
      <origin
        xyz="0 0 0"
        rpy="0 0 0" />
      <geometry>
        <mesh
          filename="package://${description_pkg}/meshes/Link1.STL" />
      </geometry>
      <material
        name="">
        <color
          rgba="0.792156862745098 0.819607843137255 0.933333333333333 1" />
      </material>
    </visual>
    <collision>
      <origin
        xyz="0 0 0"
        rpy="0 0 0" />
      <geometry>
        <mesh
          filename="package://${description_pkg}/meshes/Link1.STL" />
      </geometry>
    </collision>
  </link>
  <joint
    name="${arm_id}_joint1"
    type="revolute">
    <origin
      xyz="0 0 0.28"
      rpy="0 0 0" />
    <parent
      link="${arm_id}_base_link" />
    <child
      link="${arm_id}_Link1" />
    <axis
      xyz="0 0 -1" />
    <limit
      lower="-3.14"
      upper="3.14"
      effort="100"
      velocity="1" />
  </joint>
  <link
    name="${arm_id}_Link2">
    <inertial>
      <origin
        xyz="-0.00191502415367495 0.372447137291568 0.0492730286450249"
        rpy="0 0 0" />
      <mass
        value="34.2613834304159" />
      <inertia
        ixx="1.73347596863579"
        ixy="0.000958860727700974"
        ixz="0.000101095442336695"
        iyy="0.208398482877593"
        iyz="-0.0321183884241466"
        izz="1.8661058530115" />
    </inertial>
    <visual>
      <origin
        xyz="0 0 0"
        rpy="0 0 0" />
      <geometry>
        <mesh
          filename="package://${description_pkg}/meshes/Link2.STL" />
      </geometry>
      <material
        name="">
        <color
          rgba="0.792156862745098 0.819607843137255 0.933333333333333 1" />
      </material>
    </visual>
    <collision>
      <origin
        xyz="0 0 0"
        rpy="0 0 0" />
      <geometry>
        <mesh
          filename="package://${description_pkg}/meshes/Link2.STL" />
      </geometry>
    </collision>
  </link>
  <joint
    name="${arm_id}_joint2"
    type="revolute">
    <origin
      xyz="0.32 0.118 0.2"
      rpy="1.5708 0 3.1416" />
    <parent
      link="${arm_id}_Link1" />
    <child
      link="${arm_id}_Link2" />
    <axis
      xyz="0 0 -1" />
    <limit
      lower="-3.14"
      upper="3.14"
      effort="100"
      velocity="1" />
  </joint>
  <link
    name="${arm_id}_Link3">
    <inertial>
      <origin
        xyz="-0.119362800557993 0.183102672935243 0.0179818741927287"
        rpy="0 0 0" />
      <mass
        value="32.926389039228" />
      <inertia
        ixx="0.489915484099479"
        ixy="0.0556277114680075"
        ixz="0.00263574249535586"
        iyy="0.308931114942503"
        iyz="-0.0224354468069642"
        izz="0.601143194619664" />
    </inertial>
    <visual>
      <origin
        xyz="0 0 0"
        rpy="0 0 0" />
      <geometry>
        <mesh
          filename="package://${description_pkg}/meshes/Link3.STL" />
      </geometry>
      <material
        name="">
        <color
          rgba="0.792156862745098 0.819607843137255 0.933333333333333 1" />
      </material>
    </visual>
    <collision>
      <origin
        xyz="0 0 0"
        rpy="0 0 0" />
      <geometry>
        <mesh
          filename="package://${description_pkg}/meshes/Link3.STL" />
      </geometry>
    </collision>
  </link>
  <joint
    name="${arm_id}_joint3"
    type="revolute">
    <origin
      xyz="0 0.87 -0.102"
      rpy="3.1416 0 -1.5708" />
    <parent
      link="${arm_id}_Link2" />
    <child
      link="${arm_id}_Link3" />
    <axis
      xyz="0 0 1" />
    <limit
      lower="-3.14"
      upper="3.14"
      effort="100"
      velocity="1" />
  </joint>
  <link
    name="${arm_id}_Link4">
    <inertial>
      <origin
        xyz="0.0846416371906673 2.64594688381692E-08 0.00119929727767398"
        rpy="0 0 0" />
      <mass
        value="3.31772253710851" />
      <inertia
        ixx="0.00871539895331897"
        ixy="-4.7223477049637E-09"
        ixz="-0.000405286761999619"
        iyy="0.0128061237486537"
        iyz="-3.3976392321703E-09"
        izz="0.0127319094954166" />
    </inertial>
    <visual>
      <origin
        xyz="0 0 0"
        rpy="0 0 0" />
      <geometry>
        <mesh
          filename="package://${description_pkg}/meshes/Link4.STL" />
      </geometry>
      <material
        name="">
        <color
          rgba="0.792156862745098 0.819607843137255 0.933333333333333 1" />
      </material>
    </visual>
    <collision>
      <origin
        xyz="0 0 0"
        rpy="0 0 0" />
      <geometry>
        <mesh
          filename="package://${description_pkg}/meshes/Link4.STL" />
      </geometry>
    </collision>
  </link>
  <joint
    name="${arm_id}_joint4"
    type="revolute">
    <origin
      xyz="-0.2 0.8005 0.016"
      rpy="0 0 1.5708" />
    <parent
      link="${arm_id}_Link3" />
    <child
      link="${arm_id}_Link4" />
    <axis
      xyz="1 0 0" />
    <limit
      lower="-3.14"
      upper="3.14"
      effort="100"
      velocity="1" />
  </joint>
  <link
    name="${arm_id}_Link5">
    <inertial>
      <origin
        xyz="0.0763715859337177 -0.0305211337057105 0.000224178940607"
        rpy="0 0 0" />
      <mass
        value="3.22512695391301" />
      <inertia
        ixx="0.0116029366091722"
        ixy="-0.000741648900225243"
        ixz="1.90809395982669E-05"
        iyy="0.00936053122831895"
        iyz="4.51148464746391E-05"
        izz="0.0122676770615181" />
    </inertial>
    <visual>
      <origin
        xyz="0 0 0"
        rpy="0 0 0" />
      <geometry>
        <mesh
          filename="package://${description_pkg}/meshes/Link5.STL" />
      </geometry>
      <material
        name="">
        <color
          rgba="0.792156862745098 0.819607843137255 0.933333333333333 1" />
      </material>
    </visual>
    <collision>
      <origin
        xyz="0 0 0"
        rpy="0 0 0" />
      <geometry>
        <mesh
          filename="package://${description_pkg}/meshes/Link5.STL" />
      </geometry>
    </collision>
  </link>
  <joint
    name="${arm_id}_joint5"
    type="revolute">
    <origin
      xyz="0.2295 0 0.091"
      rpy="0 1.5708 0" />
    <parent
      link="${arm_id}_Link4" />
    <child
      link="${arm_id}_Link5" />
    <axis
      xyz="1 0 0" />
    <limit
      lower="-3.14"
      upper="3.14"
      effort="100"
      velocity="1" />
  </joint>
  <link
    name="${arm_id}_Link6">
    <inertial>
      <origin
        xyz="-2.22044604925031E-16 0 -0.0370741200129463"
        rpy="0 0 0" />
      <mass
        value="1.03809496696182" />
      <inertia
        ixx="0.00165602822384769"
        ixy="-5.82399022652644E-20"
        ixz="9.29208701696412E-21"
        iyy="0.00165602822384769"
        iyz="4.92674563783155E-20"
        izz="0.00254659409207582" />
    </inertial>
    <visual>
      <origin
        xyz="0 0 0"
        rpy="0 0 0" />
      <geometry>
        <mesh
          filename="package://${description_pkg}/meshes/Link6.STL" />
      </geometry>
      <material
        name="">
        <color
          rgba="0.792156862745098 0.819607843137255 0.933333333333333 1" />
      </material>
    </visual>
    <collision>
      <origin
        xyz="0 0 0"
        rpy="0 0 0" />
      <geometry>
        <mesh
          filename="package://${description_pkg}/meshes/Link6.STL" />
      </geometry>
    </collision>
  </link>
  <joint
    name="${arm_id}_joint6"
    type="revolute">
    <origin
      xyz="0.091 -0.185 0"
      rpy="1.5708 1.5708 0" />
    <parent
      link="${arm_id}_Link5" />
    <child
      link="${arm_id}_Link6" />
    <axis
      xyz="0 0 1" />
    <limit
      lower="-3.14"
      upper="3.14"
      effort="100"
      velocity="1" />
  </joint>
 </xacro:macro>
</robot>
