<?xml version="1.0" encoding="utf-8"?>
<!-- This URDF was automatically created by SolidWorks to URDF Exporter! Originally created by Stephen Brawner (brawner@gmail.com) 
     Commit Version: 1.6.0-1-g15f4949  Build Version: 1.6.7594.29634
     For more information, please see http://wiki.ros.org/sw_urdf_exporter -->
<robot
  name="hg_arm_bend_description">
  <link
    name="base_link">
    <inertial>
      <origin
        xyz="-0.0980500358272937 -0.00232771681565317 0.111852076506816"
        rpy="0 0 0" />
      <mass
        value="46.5873146529749" />
      <inertia
        ixx="0.661474745111325"
        ixy="0.0153527675183583"
        ixz="0.089604953466729"
        iyy="1.33815915829418"
        iyz="0.000457536691791633"
        izz="1.80453325697265" />
    </inertial>
    <visual>
      <origin
        xyz="0 0 0"
        rpy="0 0 0" />
      <geometry>
        <mesh
          filename="package://hg_arm_bend_description/meshes/base_link.STL" />
      </geometry>
      <material
        name="">
        <color
          rgba="0.792156862745098 0.819607843137255 0.933333333333333 1" />
      </material>
    </visual>
    <collision>
      <origin
        xyz="0 0 0"
        rpy="0 0 0" />
      <geometry>
        <mesh
          filename="package://hg_arm_bend_description/meshes/base_link.STL" />
      </geometry>
    </collision>
  </link>
  <link
    name="Link1">
    <inertial>
      <origin
        xyz="0.124489041830363 -0.0393581743666849 0.118219762696502"
        rpy="0 0 0" />
      <mass
        value="33.6330721032145" />
      <inertia
        ixx="0.468945917191167"
        ixy="-0.0589086007459388"
        ixz="-0.222059127182104"
        iyy="0.888555909380165"
        iyz="-0.0161423969222272"
        izz="0.843325415823868" />
    </inertial>
    <visual>
      <origin
        xyz="0 0 0"
        rpy="0 0 0" />
      <geometry>
        <mesh
          filename="package://hg_arm_bend_description/meshes/Link1.STL" />
      </geometry>
      <material
        name="">
        <color
          rgba="0.792156862745098 0.819607843137255 0.933333333333333 1" />
      </material>
    </visual>
    <collision>
      <origin
        xyz="0 0 0"
        rpy="0 0 0" />
      <geometry>
        <mesh
          filename="package://hg_arm_bend_description/meshes/Link1.STL" />
      </geometry>
    </collision>
  </link>
  <joint
    name="joint1"
    type="revolute">
    <origin
      xyz="0 0 0.28"
      rpy="0 0 0" />
    <parent
      link="base_link" />
    <child
      link="Link1" />
    <axis
      xyz="0 0 -1" />
    <limit
      lower="-3.14"
      upper="3.14"
      effort="1"
      velocity="1" />
  </joint>
  <link
    name="Link2">
    <inertial>
      <origin
        xyz="-0.00191502415367473 -0.0672730286474408 0.372447137291563"
        rpy="0 0 0" />
      <mass
        value="34.2613834304154" />
      <inertia
        ixx="1.7334759524833"
        ixy="-0.000101095446454565"
        ixz="0.000958860727692765"
        iyy="1.86610585301145"
        iyz="0.0321183884522118"
        izz="0.208398466725149" />
    </inertial>
    <visual>
      <origin
        xyz="0 0 0"
        rpy="0 0 0" />
      <geometry>
        <mesh
          filename="package://hg_arm_bend_description/meshes/Link2.STL" />
      </geometry>
      <material
        name="">
        <color
          rgba="0.792156862745098 0.819607843137255 0.933333333333333 1" />
      </material>
    </visual>
    <collision>
      <origin
        xyz="0 0 0"
        rpy="0 0 0" />
      <geometry>
        <mesh
          filename="package://hg_arm_bend_description/meshes/Link2.STL" />
      </geometry>
    </collision>
  </link>
  <joint
    name="joint2"
    type="revolute">
    <origin
      xyz="0.32 0.1 0.2"
      rpy="0 0 3.1416" />
    <parent
      link="Link1" />
    <child
      link="Link2" />
    <axis
      xyz="0 -1 0" />
    <limit
      lower="-3.14"
      upper="3.14"
      effort="1"
      velocity="1" />
  </joint>
  <link
    name="Link3">
    <inertial>
      <origin
        xyz="-0.183102672704758 0.017981874347669 0.119362800384375"
        rpy="0 0 0" />
      <mass
        value="32.9263890108208" />
      <inertia
        ixx="0.308931114884525"
        ixy="0.0224354465402859"
        ixz="0.055627711648795"
        iyy="0.601143194786424"
        iyz="-0.00263574311954439"
        izz="0.489915483725197" />
    </inertial>
    <visual>
      <origin
        xyz="0 0 0"
        rpy="0 0 0" />
      <geometry>
        <mesh
          filename="package://hg_arm_bend_description/meshes/Link3.STL" />
      </geometry>
      <material
        name="">
        <color
          rgba="0.792156862745098 0.819607843137255 0.933333333333333 1" />
      </material>
    </visual>
    <collision>
      <origin
        xyz="0 0 0"
        rpy="0 0 0" />
      <geometry>
        <mesh
          filename="package://hg_arm_bend_description/meshes/Link3.STL" />
      </geometry>
    </collision>
  </link>
  <joint
    name="joint3"
    type="revolute">
    <origin
      xyz="0 0.084 0.87"
      rpy="0 0 0" />
    <parent
      link="Link2" />
    <child
      link="Link3" />
    <axis
      xyz="0 1 0" />
    <limit
      lower="-3.14"
      upper="3.14"
      effort="1"
      velocity="1" />
  </joint>
  <link
    name="Link4">
    <inertial>
      <origin
        xyz="0.0251416371906672 -2.64594692822584E-08 -0.00119929727767354"
        rpy="0 0 0" />
      <mass
        value="3.31772253710851" />
      <inertia
        ixx="0.00871539895331899"
        ixy="4.72234769705073E-09"
        ixz="0.000405286761999623"
        iyy="0.0128061237486537"
        iyz="-3.39763923044189E-09"
        izz="0.0127319094954166" />
    </inertial>
    <visual>
      <origin
        xyz="0 0 0"
        rpy="0 0 0" />
      <geometry>
        <mesh
          filename="package://hg_arm_bend_description/meshes/Link4.STL" />
      </geometry>
      <material
        name="">
        <color
          rgba="0.792156862745098 0.819607843137255 0.933333333333333 1" />
      </material>
    </visual>
    <collision>
      <origin
        xyz="0 0 0"
        rpy="0 0 0" />
      <geometry>
        <mesh
          filename="package://hg_arm_bend_description/meshes/Link4.STL" />
      </geometry>
    </collision>
  </link>
  <joint
    name="joint4"
    type="revolute">
    <origin
      xyz="-0.86 0.016 0.2"
      rpy="-1.5708 0 3.1416" />
    <parent
      link="Link3" />
    <child
      link="Link4" />
    <axis
      xyz="1 0 0" />
    <limit
      lower="-3.14"
      upper="3.14"
      effort="1"
      velocity="1" />
  </joint>
  <link
    name="Link5">
    <inertial>
      <origin
        xyz="0.0761284567626129 -0.0236687427949571 0.0192511620493179"
        rpy="0 0 0" />
      <mass
        value="3.21802266833736" />
      <inertia
        ixx="0.0115685195832536"
        ixy="-0.000566862871540121"
        ixz="0.000478618021045719"
        iyy="0.010525417907517"
        iyz="0.00142169346768481"
        izz="0.0110683735994668" />
    </inertial>
    <visual>
      <origin
        xyz="0 0 0"
        rpy="0 0 0" />
      <geometry>
        <mesh
          filename="package://hg_arm_bend_description/meshes/Link5.STL" />
      </geometry>
      <material
        name="">
        <color
          rgba="0.792156862745098 0.819607843137255 0.933333333333333 1" />
      </material>
    </visual>
    <collision>
      <origin
        xyz="0 0 0"
        rpy="0 0 0" />
      <geometry>
        <mesh
          filename="package://hg_arm_bend_description/meshes/Link5.STL" />
      </geometry>
    </collision>
  </link>
  <joint
    name="joint5"
    type="revolute">
    <origin
      xyz="0.17 0 -0.087"
      rpy="-2.26689 -1.5708 0" />
    <parent
      link="Link4" />
    <child
      link="Link5" />
    <axis
      xyz="1 0 0" />
    <limit
      lower="-3.14"
      upper="3.14"
      effort="1"
      velocity="1" />
  </joint>
  <link
    name="Link6">
    <inertial>
      <origin
        xyz="0 0 0.0179258799870539"
        rpy="0 0 0" />
      <mass
        value="1.03809496696182" />
      <inertia
        ixx="0.00165602822384769"
        ixy="2.71050543121376E-19"
        ixz="7.25060202849681E-19"
        iyy="0.00165602822384768"
        iyz="-3.03576608295941E-18"
        izz="0.00254659409207581" />
    </inertial>
    <visual>
      <origin
        xyz="0 0 0"
        rpy="0 0 0" />
      <geometry>
        <mesh
          filename="package://hg_arm_bend_description/meshes/Link6.STL" />
      </geometry>
      <material
        name="">
        <color
          rgba="0.792156862745098 0.819607843137255 0.933333333333333 1" />
      </material>
    </visual>
    <collision>
      <origin
        xyz="0 0 0"
        rpy="0 0 0" />
      <geometry>
        <mesh
          filename="package://hg_arm_bend_description/meshes/Link6.STL" />
      </geometry>
    </collision>
  </link>
  <joint
    name="joint6"
    type="revolute">
    <origin
      xyz="0.091 -0.10145 0.081284"
      rpy="0.89022 -0.11255 0.090681" />
    <parent
      link="Link5" />
    <child
      link="Link6" />
    <axis
      xyz="0 0 1" />
    <limit
      lower="-3.14"
      upper="3.14"
      effort="1"
      velocity="1" />
  </joint>
  <link
    name="gripper">
    <inertial>
      <origin
        xyz="-0.000800000000000023 -0.0953720583235611 -0.208781587074253"
        rpy="0 0 0" />
      <mass
        value="0.843628368630204" />
      <inertia
        ixx="0.00120327643820655"
        ixy="3.98377889713135E-06"
        ixz="-2.78947201433193E-06"
        iyy="0.00157497092398128"
        iyz="0.000538997184197691"
        izz="0.0019673287867838" />
    </inertial>
    <visual>
      <origin
        xyz="0 0 0"
        rpy="0 0 0" />
      <geometry>
        <mesh
          filename="package://hg_arm_bend_description/meshes/gripper.STL" />
      </geometry>
      <material
        name="">
        <color
          rgba="0.866666666666667 0.866666666666667 0.890196078431372 1" />
      </material>
    </visual>
    <collision>
      <origin
        xyz="0 0 0"
        rpy="0 0 0" />
      <geometry>
        <mesh
          filename="package://hg_arm_bend_description/meshes/gripper.STL" />
      </geometry>
    </collision>
  </link>
  <joint
    name="gripper"
    type="fixed">
    <origin
      xyz="-0.0074525 -0.040963 0.2905"
      rpy="0.61087 0 0" />
    <parent
      link="Link6" />
    <child
      link="gripper" />
    <axis
      xyz="0 0 0" />
  </joint>
  <link
    name="finger1">
    <inertial>
      <origin
        xyz="-0.0149825561728722 0.00766914135821395 0.0163030997564393"
        rpy="0 0 0" />
      <mass
        value="0.136847072523442" />
      <inertia
        ixx="0.000137531297377429"
        ixy="2.8724798129231E-06"
        ixz="6.77437980169981E-06"
        iyy="0.000116059899006359"
        iyz="-4.07993447332033E-05"
        izz="2.59700971449525E-05" />
    </inertial>
    <visual>
      <origin
        xyz="0 0 0"
        rpy="0 0 0" />
      <geometry>
        <mesh
          filename="package://hg_arm_bend_description/meshes/finger1.STL" />
      </geometry>
      <material
        name="">
        <color
          rgba="0.776470588235294 0.756862745098039 0.737254901960784 1" />
      </material>
    </visual>
    <collision>
      <origin
        xyz="0 0 0"
        rpy="0 0 0" />
      <geometry>
        <mesh
          filename="package://hg_arm_bend_description/meshes/finger1.STL" />
      </geometry>
    </collision>
  </link>
  <joint
    name="finger1"
    type="prismatic">
    <origin
      xyz="-0.0226 -0.0096577 -0.08663"
      rpy="0.61087 0 3.1416" />
    <parent
      link="gripper" />
    <child
      link="finger1" />
    <axis
      xyz="1 0 0" />
    <limit
      lower="0"
      upper="0.04"
      effort="20"
      velocity="1" />
  </joint>
  <link
    name="finger2">
    <inertial>
      <origin
        xyz="0.0151825561728721 0.0076691413582135 0.0163030997564396"
        rpy="0 0 0" />
      <mass
        value="0.136847072523442" />
      <inertia
        ixx="0.000137531297377429"
        ixy="-2.87247981292306E-06"
        ixz="-6.77437980169975E-06"
        iyy="0.000116059899006359"
        iyz="-4.07993447332036E-05"
        izz="2.59700971449525E-05" />
    </inertial>
    <visual>
      <origin
        xyz="0 0 0"
        rpy="0 0 0" />
      <geometry>
        <mesh
          filename="package://hg_arm_bend_description/meshes/finger2.STL" />
      </geometry>
      <material
        name="">
        <color
          rgba="0.796078431372549 0.823529411764706 0.937254901960784 1" />
      </material>
    </visual>
    <collision>
      <origin
        xyz="0 0 0"
        rpy="0 0 0" />
      <geometry>
        <mesh
          filename="package://hg_arm_bend_description/meshes/finger2.STL" />
      </geometry>
    </collision>
  </link>
  <joint
    name="finger2"
    type="prismatic">
    <origin
      xyz="0.0212 -0.0096577 -0.08663"
      rpy="0.61087 0 3.1416" />
    <parent
      link="gripper" />
    <child
      link="finger2" />
    <axis
      xyz="-1 0 0" />
    <limit
      lower="0"
      upper="0.04"
      effort="20"
      velocity="1" />
  </joint>
</robot>
